Workbook

Sheet README
A1: MarginLab Pricing Lab — Operating Manual
A3: What this workbook does
A4: Takes your café menu, your costs, and (optionally) your sales history, and recommends a price for each item that improves profit while respecting psychological pricing rules, role-based caps, and reversibility constraints.
A6: How to use it (the short version)
A7: Step 1 — SETTINGS: pick currency, rounding step, ending preference, and guardrails. Step 2 — OWNER_INPUTS: enter your menu (name, category, role, cost, current price, monthly units). Step 3 — (optional) COMPETITOR_BENCHMARK: enter prices from 2-3 nearby cafés for items where market context matters. Step 4 — (optional) SALES_DATA: paste at least 60 daily price+quantity rows per item where you have real history. The model will estimate elasticity from your data. Step 5 — OWNER_RESULTS: read the headline lift, per-item recommendations, sensitivity check, and any data-quality warnings. Step 6 — QA_CHECKS: review any FLAG or FAIL items before sharing the file with a client.
A9: What gets calculated
A10: For each item: the profit-maximizing price under economic theory (Lerner), shrunk toward current price by a confidence factor, clamped to role and global guardrails, threshold-pulled below psychological round numbers, optionally snapped to charm endings (USD only), and rounded to the configured step. The workbook also computes the menu-engineering quadrant for each item, runs a three-scenario sensitivity analysis on elasticity, and (optionally) compares recommendations against local competitor prices.
A12: What "confidence" means here
A13: If you have given the model real daily sales data with genuine price variation, it estimates the price sensitivity of each item statistically and uses the high-confidence path. If you have not (most cafés have not), the model uses category-level priors and the low-confidence path, which produces smaller, more cautious recommendations and labels them "Pilot first."
A15: Sheets you (the owner) need to touch
A16: SETTINGS, OWNER_INPUTS, OWNER_RESULTS, and optionally COMPETITOR_BENCHMARK. Everything else is internal machinery — do not edit unless you know exactly what you are doing.
A18: Sheets the consultant operates
... A30: Quick navigation
A31: =HYPERLINK("#'SETTINGS'!A1","SETTINGS") -> SETTINGS | B31: Currency, rounding, guardrails, demo toggle
A32: =HYPERLINK("#'OWNER_INPUTS'!A1","OWNER_INPUTS") -> OWNER_INPUTS | B32: Your menu — name, category, role, cost, price, monthly units
A33: =HYPERLINK("#'COMPETITOR_BENCHMARK'!A1","COMPETITOR_BENCHMARK") -> COMPETITOR_BENCHMARK | B33: (Optional) local competitor prices and market position
A34: =HYPERLINK("#'OWNER_RESULTS'!A1","OWNER_RESULTS") -> OWNER_RESULTS | B34: The headline: lift, per-item recommendations, sensitivity
A35: =HYPERLINK("#'CATEGORY_PRIORS'!A1","CATEGORY_PRIORS") -> CATEGORY_PRIORS | B35: Default elasticities by category (used when no sales data)
A36: =HYPERLINK("#'PSYCHOLOGY_RULES'!A1","PSYCHOLOGY_RULES") -> PSYCHOLOGY_RULES | B36: Role caps and price-threshold pullbacks
A37: =HYPERLINK("#'MENU_ENGINEERING'!A1","MENU_ENGINEERING") -> MENU_ENGINEERING | B37: Star / Plowhorse / Puzzle / Dog classification
A38: =HYPERLINK("#'SALES_DATA'!A1","SALES_DATA") -> SALES_DATA | B38: (Optional) daily sales for elasticity estimation
A39: =HYPERLINK("#'CALIBRATION'!A1","CALIBRATION") -> CALIBRATION | B39: Per-item elasticity estimates with confidence intervals
A40: =HYPERLINK("#'OPTIMIZER'!A1","OPTIMIZER") -> OPTIMIZER | B40: Full Lerner → shrinkage → caps → rounding pipeline
A41: =HYPERLINK("#'SENSITIVITY'!A1","SENSITIVITY") -> SENSITIVITY | B41: Conservative / Baseline / Optimistic profit lift scenarios
A42: =HYPERLINK("#'QA_CHECKS'!A1","QA_CHECKS") -> QA_CHECKS | B42: Data-quality and model-sanity checks

Sheet SETTINGS
A1: Global Settings
A3: Currency & Rounding
A4: Currency | B4: USD | C4: Choose USD or IDR. Drives rounding and threshold rules.
A5: Round to nearest | B5: 0.1 | C5: For small-denomination currencies (USD/EUR/GBP/AUD/CAD): 0.01, 0.05, 0.10, 0.50, 1.00. For large-denomination currencies (IDR/JPY/VND): 500, 1000, 5000.
A6: Price ending preference | B6: .00 | C6: Examples: ".00", ".50", ".90", ".95", ".99". Used only when round_to ≤ 0.50 (i.e., small-denomination currencies like USD/EUR/GBP). Auto-disabled for high-denomination currencies like IDR/JPY. ".00" = no charm. Direction-preserving: charm never reverses the analytical recommendation.
A8: Global Guardrails
A9: Max raise per item | B9: 0.1 | C9: +10% by default. The single largest price increase the model will ever recommend.
A10: Max cut per item | B10: -0.05 | C10: -5% by default. The single largest price decrease the model will ever recommend.
A11: Confidence shrinkage (HIGH) | B11: 1 | C11: How much of the Lerner-optimal move to take when confidence is HIGH. 1.0 = take it all.
A12: Confidence shrinkage (MEDIUM) | B12: 0.5 | C12: How much of the Lerner-optimal move to take when confidence is MEDIUM.
A13: Confidence shrinkage (LOW) | B13: 0.25 | C13: How much of the Lerner-optimal move to take when confidence is LOW (prior only).
A15: Demo / Production Toggle
A16: Use sample SALES_DATA | B16: No | C16: "Yes" = run the model against the built-in synthetic demo. "No" = client production mode (uses category priors unless the client gives you real data).

Sheet OWNER_INPUTS
A1: Your Menu — Edit Here
A3: Fill in your real menu below. Up to 30 items. The recommendations on OWNER_RESULTS update automatically.
A5: # | B5: Item Name | C5: Category | D5: Role | E5: Cost per unit | F5: Current Price | G5: Units sold last month | H5: Notes (optional)
A6: 1 | B6: Flat White | C6: Coffee | D6: Traffic Driver | E6: 1 | F6: 4.2 | G6: 1500 | H6: Entry price — protect.
A7: 2 | B7: Matcha Latte | C7: Specialty Drink | D7: Profit Driver | E7: 1.4 | F7: 4.8 | G7: 1200 | H7: Higher margin specialty.
A8: 3 | B8: Eggs Benedict | C8: Sandwich/Food | D8: Signature | E8: 4.2 | F8: 9.8 | G8: 900 | H8: Brunch hero item.
A9: 4 | B9: Avocado Toast | C9: Sandwich/Food | D9: Core | E9: 4.5 | F9: 10.5 | G9: 1050
A10: 5 | B10: Pancakes | C10: Pastry | D10: Premium Anchor | E10: 3.5 | F10: 8.8 | G10: 750
A11: 6 | B11: Cheesecake | C11: Dessert | D11: Profit Driver | E11: 2.1 | F11: 5.8 | G11: 450 | H11: Pair with coffee.
A12: 7
A13: 8
A14: 9
A15: 10
A16: 11
A17: 12
A18: 13
A19: 14
A20: 15
A21: 16
A22: 17
A23: 18
... A35: 30
A37: How to use this tab:
A38: 1. | B38: Replace the 6 demo rows with your real menu. Use the dropdowns for Category and Role.
A39: 2. | B39: "Cost per unit" = what you pay in ingredients/labor to make ONE serving. Net of taxes.
A40: 3. | B40: "Units sold last month" = approximate monthly volume per item. ±20% is fine.
A41: 4. | B41: "Role" tells the model how aggressively to move each item. Use Traffic Driver for entry items the customer expects to be sharp. Use Profit Driver / Premium Anchor / Signature for items that can carry margin. Use Core for everyday items in between.
A42: 5. | B42: Open the OWNER_RESULTS tab to see what to do.

Sheet COMPETITOR_BENCHMARK
A1: Competitor Benchmark — Local Market Pricing Context
A3: Optional. Enter prices from 2–3 nearby cafés for items where market context matters (visible traffic drivers, signature items). The market average, min, and max are computed automatically. A flag fires in the rightmost column if the recommended price falls outside the local market range by more than the tolerance set below.
A5: Tolerance above market max | B5: 0.2 | C5: Default 20%. Recommendations more than this above market max are flagged "Above market."
A6: Tolerance below market min | B6: 0.2 | C6: Default 20%. Recommendations more than this below market min are flagged "Below market."
A8: # | B8: Item | C8: Current price | D8: Competitor 1 | E8: Competitor 2 | F8: Competitor 3 | G8: Market avg | H8: Market min | I8: Market max | J8: Rec price | K8: Position | L8: Flag
A9: 1 | B9: =IF(OWNER_INPUTS!B6="","",OWNER_INPUTS!B6) -> Flat White | C9: =IF($B9="","",OWNER_INPUTS!F6) -> 4.2 | G9: =IF($B9="","",IFERROR(AVERAGE($D9:$F9),"")) | H9: =IF($B9="","",IFERROR(IF(COUNT($D9:$F9)>0,MIN($D9:$F9),""),"")) | I9: =IF($B9="","",IFERROR(IF(COUNT($D9:$F9)>0,MAX($D9:$F9),""),"")) | J9: =IF($B9="","",OPTIMIZER!T6) -> 4.3 | K9: =IF($B9="","",IF(OR($G9="",NOT(ISNUMBER($G9))),"No comp data",IF($J9>$I9*(1+$B$5),"Above market",IF($J9<$H9*(1-$B$6),"Below market","Within market")))) -> No comp data | L9: =IF($B9="","",IF($K9="Above market","⚠ Above local market by >"&TEXT($B$5,"0%"),IF($K9="Below market","⚠ Below local market by >"&TEXT($B$6,"0%"),"")))
A10: 2 | B10: =IF(OWNER_INPUTS!B7="","",OWNER_INPUTS!B7) -> Matcha Latte | C10: =IF($B10="","",OWNER_INPUTS!F7) -> 4.8 | G10: =IF($B10="","",IFERROR(AVERAGE($D10:$F10),"")) | H10: =IF($B10="","",IFERROR(IF(COUNT($D10:$F10)>0,MIN($D10:$F10),""),"")) | I10: =IF($B10="","",IFERROR(IF(COUNT($D10:$F10)>0,MAX($D10:$F10),""),"")) | J10: =IF($B10="","",OPTIMIZER!T7) -> 4.9 | K10: =IF($B10="","",IF(OR($G10="",NOT(ISNUMBER($G10))),"No comp data",IF($J10>$I10*(1+$B$5),"Above market",IF($J10<$H10*(1-$B$6),"Below market","Within market")))) -> No comp data | L10: =IF($B10="","",IF($K10="Above market","⚠ Above local market by >"&TEXT($B$5,"0%"),IF($K10="Below market","⚠ Below local market by >"&TEXT($B$6,"0%"),"")))
A11: 3 | B11: =IF(OWNER_INPUTS!B8="","",OWNER_INPUTS!B8) -> Eggs Benedict | C11: =IF($B11="","",OWNER_INPUTS!F8) -> 9.8 | G11: =IF($B11="","",IFERROR(AVERAGE($D11:$F11),"")) | H11: =IF($B11="","",IFERROR(IF(COUNT($D11:$F11)>0,MIN($D11:$F11),""),"")) | I11: =IF($B11="","",IFERROR(IF(COUNT($D11:$F11)>0,MAX($D11:$F11),""),"")) | J11: =IF($B11="","",OPTIMIZER!T8) -> 9.9 | K11: =IF($B11="","",IF(OR($G11="",NOT(ISNUMBER($G11))),"No comp data",IF($J11>$I11*(1+$B$5),"Above market",IF($J11<$H11*(1-$B$6),"Below market","Within market")))) -> No comp data | L11: =IF($B11="","",IF($K11="Above market","⚠ Above local market by >"&TEXT($B$5,"0%"),IF($K11="Below market","⚠ Below local market by >"&TEXT($B$6,"0%"),"")))
A12: 4 | B12: =IF(OWNER_INPUTS!B9="","",OWNER_INPUTS!B9) -> Avocado Toast | C12: =IF($B12="","",OWNER_INPUTS!F9) -> 10.5 | G12: =IF($B12="","",IFERROR(AVERAGE($D12:$F12),"")) | H12: =IF($B12="","",IFERROR(IF(COUNT($D12:$F12)>0,MIN($D12:$F12),""),"")) | I12: =IF($B12="","",IFERROR(IF(COUNT($D12:$F12)>0,MAX($D12:$F12),""),"")) | J12: =IF($B12="","",OPTIMIZER!T9) -> 10.7 | K12: =IF($B12="","",IF(OR($G12="",NOT(ISNUMBER($G12))),"No comp data",IF($J12>$I12*(1+$B$5),"Above market",IF($J12<$H12*(1-$B$6),"Below market","Within market")))) -> No comp data | L12: =IF($B12="","",IF($K12="Above market","⚠ Above local market by >"&TEXT($B$5,"0%"),IF($K12="Below market","⚠ Below local market by >"&TEXT($B$6,"0%"),"")))
A13: 5 | B13: =IF(OWNER_INPUTS!B10="","",OWNER_INPUTS!B10) -> Pancakes | C13: =IF($B13="","",OWNER_INPUTS!F10) -> 8.8 | G13: =IF($B13="","",IFERROR(AVERAGE($D13:$F13),"")) | H13: =IF($B13="","",IFERROR(IF(COUNT($D13:$F13)>0,MIN($D13:$F13),""),"")) | I13: =IF($B13="","",IFERROR(IF(COUNT($D13:$F13)>0,MAX($D13:$F13),""),"")) | J13: =IF($B13="","",OPTIMIZER!T10) -> 9.2 | K13: =IF($B13="","",IF(OR($G13="",NOT(ISNUMBER($G13))),"No comp data",IF($J13>$I13*(1+$B$5),"Above market",IF($J13<$H13*(1-$B$6),"Below market","Within market")))) -> No comp data | L13: =IF($B13="","",IF($K13="Above market","⚠ Above local market by >"&TEXT($B$5,"0%"),IF($K13="Below market","⚠ Below local market by >"&TEXT($B$6,"0%"),"")))
A14: 6 | B14: =IF(OWNER_INPUTS!B11="","",OWNER_INPUTS!B11) -> Cheesecake | C14: =IF($B14="","",OWNER_INPUTS!F11) -> 5.8 | G14: =IF($B14="","",IFERROR(AVERAGE($D14:$F14),"")) | H14: =IF($B14="","",IFERROR(IF(COUNT($D14:$F14)>0,MIN($D14:$F14),""),"")) | I14: =IF($B14="","",IFERROR(IF(COUNT($D14:$F14)>0,MAX($D14:$F14),""),"")) | J14: =IF($B14="","",OPTIMIZER!T11) -> 6.1 | K14: =IF($B14="","",IF(OR($G14="",NOT(ISNUMBER($G14))),"No comp data",IF($J14>$I14*(1+$B$5),"Above market",IF($J14<$H14*(1-$B$6),"Below market","Within market")))) -> No comp data | L14: =IF($B14="","",IF($K14="Above market","⚠ Above local market by >"&TEXT($B$5,"0%"),IF($K14="Below market","⚠ Below local market by >"&TEXT($B$6,"0%"),"")))
A15: 7 | B15: =IF(OWNER_INPUTS!B12="","",OWNER_INPUTS!B12) | C15: =IF($B15="","",OWNER_INPUTS!F12) | G15: =IF($B15="","",IFERROR(AVERAGE($D15:$F15),"")) | H15: =IF($B15="","",IFERROR(IF(COUNT($D15:$F15)>0,MIN($D15:$F15),""),"")) | I15: =IF($B15="","",IFERROR(IF(COUNT($D15:$F15)>0,MAX($D15:$F15),""),"")) | J15: =IF($B15="","",OPTIMIZER!T12) | K15: =IF($B15="","",IF(OR($G15="",NOT(ISNUMBER($G15))),"No comp data",IF($J15>$I15*(1+$B$5),"Above market",IF($J15<$H15*(1-$B$6),"Below market","Within market")))) | L15: =IF($B15="","",IF($K15="Above market","⚠ Above local market by >"&TEXT($B$5,"0%"),IF($K15="Below market","⚠ Below local market by >"&TEXT($B$6,"0%"),"")))
A16: 8 | B16: =IF(OWNER_INPUTS!B13="","",OWNER_INPUTS!B13) | C16: =IF($B16="","",OWNER_INPUTS!F13) | G16: =IF($B16="","",IFERROR(AVERAGE($D16:$F16),"")) | H16: =IF($B16="","",IFERROR(IF(COUNT($D16:$F16)>0,MIN($D16:$F16),""),"")) | I16: =IF($B16="","",IFERROR(IF(COUNT($D16:$F16)>0,MAX($D16:$F16),""),"")) | J16: =IF($B16="","",OPTIMIZER!T13) | K16: =IF($B16="","",IF(OR($G16="",NOT(ISNUMBER($G16))),"No comp data",IF($J16>$I16*(1+$B$5),"Above market",IF($J16<$H16*(1-$B$6),"Below market","Within market")))) | L16: =IF($B16="","",IF($K16="Above market","⚠ Above local market by >"&TEXT($B$5,"0%"),IF($K16="Below market","⚠ Below local market by >"&TEXT($B$6,"0%"),"")))
A17: 9 | B17: =IF(OWNER_INPUTS!B14="","",OWNER_INPUTS!B14) | C17: =IF($B17="","",OWNER_INPUTS!F14) | G17: =IF($B17="","",IFERROR(AVERAGE($D17:$F17),"")) | H17: =IF($B17="","",IFERROR(IF(COUNT($D17:$F17)>0,MIN($D17:$F17),""),"")) | I17: =IF($B17="","",IFERROR(IF(COUNT($D17:$F17)>0,MAX($D17:$F17),""),"")) | J17: =IF($B17="","",OPTIMIZER!T14) | K17: =IF($B17="","",IF(OR($G17="",NOT(ISNUMBER($G17))),"No comp data",IF($J17>$I17*(1+$B$5),"Above market",IF($J17<$H17*(1-$B$6),"Below market","Within market")))) | L17: =IF($B17="","",IF($K17="Above market","⚠ Above local market by >"&TEXT($B$5,"0%"),IF($K17="Below market","⚠ Below local market by >"&TEXT($B$6,"0%"),"")))
A18: 10 | B18: =IF(OWNER_INPUTS!B15="","",OWNER_INPUTS!B15) | C18: =IF($B18="","",OWNER_INPUTS!F15) | G18: =IF($B18="","",IFERROR(AVERAGE($D18:$F18),"")) | H18: =IF($B18="","",IFERROR(IF(COUNT($D18:$F18)>0,MIN($D18:$F18),""),"")) | I18: =IF($B18="","",IFERROR(IF(COUNT($D18:$F18)>0,MAX($D18:$F18),""),"")) | J18: =IF($B18="","",OPTIMIZER!T15) | K18: =IF($B18="","",IF(OR($G18="",NOT(ISNUMBER($G18))),"No comp data",IF($J18>$I18*(1+$B$5),"Above market",IF($J18<$H18*(1-$B$6),"Below market","Within market")))) | L18: =IF($B18="","",IF($K18="Above market","⚠ Above local market by >"&TEXT($B$5,"0%"),IF($K18="Below market","⚠ Below local market by >"&TEXT($B$6,"0%"),"")))
A19: 11 | B19: =IF(OWNER_INPUTS!B16="","",OWNER_INPUTS!B16) | C19: =IF($B19="","",OWNER_INPUTS!F16) | G19: =IF($B19="","",IFERROR(AVERAGE($D19:$F19),"")) | H19: =IF($B19="","",IFERROR(IF(COUNT($D19:$F19)>0,MIN($D19:$F19),""),"")) | I19: =IF($B19="","",IFERROR(IF(COUNT($D19:$F19)>0,MAX($D19:$F19),""),"")) | J19: =IF($B19="","",OPTIMIZER!T16) | K19: =IF($B19="","",IF(OR($G19="",NOT(ISNUMBER($G19))),"No comp data",IF($J19>$I19*(1+$B$5),"Above market",IF($J19<$H19*(1-$B$6),"Below market","Within market")))) | L19: =IF($B19="","",IF($K19="Above market","⚠ Above local market by >"&TEXT($B$5,"0%"),IF($K19="Below market","⚠ Below local market by >"&TEXT($B$6,"0%"),"")))
A20: 12 | B20: =IF(OWNER_INPUTS!B17="","",OWNER_INPUTS!B17) | C20: =IF($B20="","",OWNER_INPUTS!F17) | G20: =IF($B20="","",IFERROR(AVERAGE($D20:$F20),"")) | H20: =IF($B20="","",IFERROR(IF(COUNT($D20:$F20)>0,MIN($D20:$F20),""),"")) | I20: =IF($B20="","",IFERROR(IF(COUNT($D20:$F20)>0,MAX($D20:$F20),""),"")) | J20: =IF($B20="","",OPTIMIZER!T17) | K20: =IF($B20="","",IF(OR($G20="",NOT(ISNUMBER($G20))),"No comp data",IF($J20>$I20*(1+$B$5),"Above market",IF($J20<$H20*(1-$B$6),"Below market","Within market")))) | L20: =IF($B20="","",IF($K20="Above market","⚠ Above local market by >"&TEXT($B$5,"0%"),IF($K20="Below market","⚠ Below local market by >"&TEXT($B$6,"0%"),"")))
... A38: 30 | B38: =IF(OWNER_INPUTS!B35="","",OWNER_INPUTS!B35) | C38: =IF($B38="","",OWNER_INPUTS!F35) | G38: =IF($B38="","",IFERROR(AVERAGE($D38:$F38),"")) | H38: =IF($B38="","",IFERROR(IF(COUNT($D38:$F38)>0,MIN($D38:$F38),""),"")) | I38: =IF($B38="","",IFERROR(IF(COUNT($D38:$F38)>0,MAX($D38:$F38),""),"")) | J38: =IF($B38="","",OPTIMIZER!T35) | K38: =IF($B38="","",IF(OR($G38="",NOT(ISNUMBER($G38))),"No comp data",IF($J38>$I38*(1+$B$5),"Above market",IF($J38<$H38*(1-$B$6),"Below market","Within market")))) | L38: =IF($B38="","",IF($K38="Above market","⚠ Above local market by >"&TEXT($B$5,"0%"),IF($K38="Below market","⚠ Below local market by >"&TEXT($B$6,"0%"),"")))
A40: Summary
A41: Items with competitor data | B41: =SUMPRODUCT(($B9:$B38<>"")*(ISNUMBER($G9:$G38))) -> 0
A42: Items priced above local market | B42: =COUNTIF($K9:$K38,"Above market") -> 0
A43: Items priced below local market | B43: =COUNTIF($K9:$K38,"Below market") -> 0
A44: Items within local market range | B44: =COUNTIF($K9:$K38,"Within market") -> 0

Sheet OWNER_RESULTS
A1: Your Pricing Recommendation
A2: Based on your menu and goals. Refresh each month or after major recipe/cost changes.
A3: =IF(OR(QA_CHECKS!C14="FLAG",QA_CHECKS!C15="FLAG",QA_CHECKS!C16="FLAG",QA_CHECKS!C17="FLAG",QA_CHECKS!C24="FLAG",QA_CHECKS!C27="FAIL",QA_CHECKS!C28="FAIL",QA_CHECKS!C29="FAIL",QA_CHECKS!C30="FAIL",QA_CHECKS!C31="FAIL"),"⚠ DATA QUALITY WARNING — One or more Hard QA checks are failing. Review QA_CHECKS before showing this to a client. Headline numbers below may be misleading.","")
A4: ESTIMATED MONTHLY PROFIT LIFT | C4: AS % OF CURRENT PROFIT | E4: ITEMS WITH A CHANGE | G4: CONFIDENCE LEVEL
A5: =opt_total_lift -> 372.23205 | C5: =opt_lift_pct -> 0.014394124 | E5: =COUNTIF(OPTIMIZER!U6:U35,"<>0")-COUNTBLANK(OPTIMIZER!U6:U35)&" of "&COUNTA(OPTIMIZER!B6:B35) -> 6 of 30 | G5: =QA_CHECKS!C32 -> LOW
A7: =cfg_currency&" per month, vs current" -> USD per month, vs current | C7: =IF(opt_baseline=0,"—","based on current contribution margin") -> based on current contribution margin | E7: "Hold" = no change recommended this cycle | G7: ="Best item: "&IFERROR(INDEX(OPTIMIZER!B6:B35,MATCH(maxifs(OPTIMIZER!X6:X35,OPTIMIZER!J6:J35,"HIGH",OPTIMIZER!B6:B35,"<>"),OPTIMIZER!X6:X35,0)),IFERROR(INDEX(OPTIMIZER!B6:B35,MATCH(maxifs(OPTIMIZER!X6:X35,OPTIMIZER!J6:J35,"MEDIUM",OPTIMIZER!B6:B35,"<>"),OPTIMIZER!X6:X35,0)),IFERROR(INDEX(OPTIMIZER!B6:B35,MATCH(MAX(OPTIMIZER!X6:X35),OPTIMIZER!X6:X35,0)),"no items configured"))) -> Best item: Pancakes
A9: What to do, item by item
A10: Item | B10: Action | C10: From | D10: To | E10: Δ % | F10: Monthly Δ profit | G10: Confidence | H10: Phase | I10: Quadrant | J10: Market | K10: Narrative
A11: =IF(OPTIMIZER!B6="","",OPTIMIZER!B6) -> Flat White | B11: =IF(OPTIMIZER!B6="","",IF(ABS(OPTIMIZER!U6)<0.005,"Hold",IF(OPTIMIZER!U6>0,"Raise","Cut"))) -> Raise | C11: =IF(OPTIMIZER!B6="","",OPTIMIZER!F6) -> 4.2 | D11: =IF(OPTIMIZER!B6="","",OPTIMIZER!T6) -> 4.3 | E11: =IF(OPTIMIZER!B6="","",OPTIMIZER!U6) -> 0.023809524 | F11: =IF(OPTIMIZER!B6="","",OPTIMIZER!X6) -> 23.520374 | G11: =IF(OPTIMIZER!B6="","",OPTIMIZER!J6) -> LOW | H11: =IF(OPTIMIZER!B6="","",IF(ABS(OPTIMIZER!U6)<0.005,"Hold",IF(OPTIMIZER!J6="HIGH","Now","Pilot first"))) -> Pilot first | I11: =IF(OPTIMIZER!B6="","",MENU_ENGINEERING!K10) -> Star | J11: =IF(OPTIMIZER!B6="","",COMPETITOR_BENCHMARK!K9) -> No comp data | K11: =IF(OPTIMIZER!B6="","",IF(ABS(OPTIMIZER!U6)<0.005,"Hold. ",IF(OPTIMIZER!U6>0,IF(OPTIMIZER!U6<0.02,"Small raise. ",IF(OPTIMIZER!U6<0.05,"Modest raise. ","Notable raise. ")),IF(OPTIMIZER!U6>-0.02,"Small cut. ",IF(OPTIMIZER!U6>-0.05,"Modest cut. ","Notable cut. "))))&IF(OPTIMIZER!D6="Traffic Driver","Traffic Driver — protect entry price. ",IF(AND(OR(OPTIMIZER!D6="Signature",OPTIMIZER!D6="Premium Anchor"),MENU_ENGINEERING!K10="Dog"),OPTIMIZER!D6&" role in Dog quadrant — protect intentionally. ",IF(MENU_ENGINEERING!K10="Star","Star — protect leadership. ",IF(MENU_ENGINEERING!K10="Plowhorse","Plowhorse — capture margin. ",IF(MENU_ENGINEERING!K10="Puzzle","Puzzle — promote or reposition. ",IF(MENU_ENGINEERING!K10="Dog","Dog — consider removal. ",""))))))&IF(OPTIMIZER!J6="HIGH","Ship now.",IF(OPTIMIZER!J6="MEDIUM","Test first.","Pilot small — using prior."))) -> Modest raise. Traffic Driver — protect entry price. Pilot small — using prior.
A12: =IF(OPTIMIZER!B7="","",OPTIMIZER!B7) -> Matcha Latte | B12: =IF(OPTIMIZER!B7="","",IF(ABS(OPTIMIZER!U7)<0.005,"Hold",IF(OPTIMIZER!U7>0,"Raise","Cut"))) -> Raise | C12: =IF(OPTIMIZER!B7="","",OPTIMIZER!F7) -> 4.8 | D12: =IF(OPTIMIZER!B7="","",OPTIMIZER!T7) -> 4.9 | E12: =IF(OPTIMIZER!B7="","",OPTIMIZER!U7) -> 0.020833333 | F12: =IF(OPTIMIZER!B7="","",OPTIMIZER!X7) -> 8.914175 | G12: =IF(OPTIMIZER!B7="","",OPTIMIZER!J7) -> LOW | H12: =IF(OPTIMIZER!B7="","",IF(ABS(OPTIMIZER!U7)<0.005,"Hold",IF(OPTIMIZER!J7="HIGH","Now","Pilot first"))) -> Pilot first | I12: =IF(OPTIMIZER!B7="","",MENU_ENGINEERING!K11) -> Star | J12: =IF(OPTIMIZER!B7="","",COMPETITOR_BENCHMARK!K10) -> No comp data | K12: =IF(OPTIMIZER!B7="","",IF(ABS(OPTIMIZER!U7)<0.005,"Hold. ",IF(OPTIMIZER!U7>0,IF(OPTIMIZER!U7<0.02,"Small raise. ",IF(OPTIMIZER!U7<0.05,"Modest raise. ","Notable raise. ")),IF(OPTIMIZER!U7>-0.02,"Small cut. ",IF(OPTIMIZER!U7>-0.05,"Modest cut. ","Notable cut. "))))&IF(OPTIMIZER!D7="Traffic Driver","Traffic Driver — protect entry price. ",IF(AND(OR(OPTIMIZER!D7="Signature",OPTIMIZER!D7="Premium Anchor"),MENU_ENGINEERING!K11="Dog"),OPTIMIZER!D7&" role in Dog quadrant — protect intentionally. ",IF(MENU_ENGINEERING!K11="Star","Star — protect leadership. ",IF(MENU_ENGINEERING!K11="Plowhorse","Plowhorse — capture margin. ",IF(MENU_ENGINEERING!K11="Puzzle","Puzzle — promote or reposition. ",IF(MENU_ENGINEERING!K11="Dog","Dog — consider removal. ",""))))))&IF(OPTIMIZER!J7="HIGH","Ship now.",IF(OPTIMIZER!J7="MEDIUM","Test first.","Pilot small — using prior."))) -> Modest raise. Star — protect leadership. Pilot small — using prior.
A13: =IF(OPTIMIZER!B8="","",OPTIMIZER!B8) -> Eggs Benedict | B13: =IF(OPTIMIZER!B8="","",IF(ABS(OPTIMIZER!U8)<0.005,"Hold",IF(OPTIMIZER!U8>0,"Raise","Cut"))) -> Raise | C13: =IF(OPTIMIZER!B8="","",OPTIMIZER!F8) -> 9.8 | D13: =IF(OPTIMIZER!B8="","",OPTIMIZER!T8) -> 9.9 | E13: =IF(OPTIMIZER!B8="","",OPTIMIZER!U8) -> 0.010204082 | F13: =IF(OPTIMIZER!B8="","",OPTIMIZER!X8) -> 48.503411 | G13: =IF(OPTIMIZER!B8="","",OPTIMIZER!J8) -> LOW | H13: =IF(OPTIMIZER!B8="","",IF(ABS(OPTIMIZER!U8)<0.005,"Hold",IF(OPTIMIZER!J8="HIGH","Now","Pilot first"))) -> Pilot first | I13: =IF(OPTIMIZER!B8="","",MENU_ENGINEERING!K12) -> Dog | J13: =IF(OPTIMIZER!B8="","",COMPETITOR_BENCHMARK!K11) -> No comp data | K13: =IF(OPTIMIZER!B8="","",IF(ABS(OPTIMIZER!U8)<0.005,"Hold. ",IF(OPTIMIZER!U8>0,IF(OPTIMIZER!U8<0.02,"Small raise. ",IF(OPTIMIZER!U8<0.05,"Modest raise. ","Notable raise. ")),IF(OPTIMIZER!U8>-0.02,"Small cut. ",IF(OPTIMIZER!U8>-0.05,"Modest cut. ","Notable cut. "))))&IF(OPTIMIZER!D8="Traffic Driver","Traffic Driver — protect entry price. ",IF(AND(OR(OPTIMIZER!D8="Signature",OPTIMIZER!D8="Premium Anchor"),MENU_ENGINEERING!K12="Dog"),OPTIMIZER!D8&" role in Dog quadrant — protect intentionally. ",IF(MENU_ENGINEERING!K12="Star","Star — protect leadership. ",IF(MENU_ENGINEERING!K12="Plowhorse","Plowhorse — capture margin. ",IF(MENU_ENGINEERING!K12="Puzzle","Puzzle — promote or reposition. ",IF(MENU_ENGINEERING!K12="Dog","Dog — consider removal. ",""))))))&IF(OPTIMIZER!J8="HIGH","Ship now.",IF(OPTIMIZER!J8="MEDIUM","Test first.","Pilot small — using prior."))) -> Small raise. Signature role in Dog quadrant — protect intentionally. Pilot small — using prior.
A14: =IF(OPTIMIZER!B9="","",OPTIMIZER!B9) -> Avocado Toast | B14: =IF(OPTIMIZER!B9="","",IF(ABS(OPTIMIZER!U9)<0.005,"Hold",IF(OPTIMIZER!U9>0,"Raise","Cut"))) -> Raise | C14: =IF(OPTIMIZER!B9="","",OPTIMIZER!F9) -> 10.5 | D14: =IF(OPTIMIZER!B9="","",OPTIMIZER!T9) -> 10.7 | E14: =IF(OPTIMIZER!B9="","",OPTIMIZER!U9) -> 0.019047619 | F14: =IF(OPTIMIZER!B9="","",OPTIMIZER!X9) -> 112.47088 | G14: =IF(OPTIMIZER!B9="","",OPTIMIZER!J9) -> LOW | H14: =IF(OPTIMIZER!B9="","",IF(ABS(OPTIMIZER!U9)<0.005,"Hold",IF(OPTIMIZER!J9="HIGH","Now","Pilot first"))) -> Pilot first | I14: =IF(OPTIMIZER!B9="","",MENU_ENGINEERING!K13) -> Plowhorse | J14: =IF(OPTIMIZER!B9="","",COMPETITOR_BENCHMARK!K12) -> No comp data | K14: =IF(OPTIMIZER!B9="","",IF(ABS(OPTIMIZER!U9)<0.005,"Hold. ",IF(OPTIMIZER!U9>0,IF(OPTIMIZER!U9<0.02,"Small raise. ",IF(OPTIMIZER!U9<0.05,"Modest raise. ","Notable raise. ")),IF(OPTIMIZER!U9>-0.02,"Small cut. ",IF(OPTIMIZER!U9>-0.05,"Modest cut. ","Notable cut. "))))&IF(OPTIMIZER!D9="Traffic Driver","Traffic Driver — protect entry price. ",IF(AND(OR(OPTIMIZER!D9="Signature",OPTIMIZER!D9="Premium Anchor"),MENU_ENGINEERING!K13="Dog"),OPTIMIZER!D9&" role in Dog quadrant — protect intentionally. ",IF(MENU_ENGINEERING!K13="Star","Star — protect leadership. ",IF(MENU_ENGINEERING!K13="Plowhorse","Plowhorse — capture margin. ",IF(MENU_ENGINEERING!K13="Puzzle","Puzzle — promote or reposition. ",IF(MENU_ENGINEERING!K13="Dog","Dog — consider removal. ",""))))))&IF(OPTIMIZER!J9="HIGH","Ship now.",IF(OPTIMIZER!J9="MEDIUM","Test first.","Pilot small — using prior."))) -> Small raise. Plowhorse — capture margin. Pilot small — using prior.
A15: =IF(OPTIMIZER!B10="","",OPTIMIZER!B10) -> Pancakes | B15: =IF(OPTIMIZER!B10="","",IF(ABS(OPTIMIZER!U10)<0.005,"Hold",IF(OPTIMIZER!U10>0,"Raise","Cut"))) -> Raise | C15: =IF(OPTIMIZER!B10="","",OPTIMIZER!F10) -> 8.8 | D15: =IF(OPTIMIZER!B10="","",OPTIMIZER!T10) -> 9.2 | E15: =IF(OPTIMIZER!B10="","",OPTIMIZER!U10) -> 0.045454545 | F15: =IF(OPTIMIZER!B10="","",OPTIMIZER!X10) -> 132.3478 | G15: =IF(OPTIMIZER!B10="","",OPTIMIZER!J10) -> LOW | H15: =IF(OPTIMIZER!B10="","",IF(ABS(OPTIMIZER!U10)<0.005,"Hold",IF(OPTIMIZER!J10="HIGH","Now","Pilot first"))) -> Pilot first | I15: =IF(OPTIMIZER!B10="","",MENU_ENGINEERING!K14) -> Dog | J15: =IF(OPTIMIZER!B10="","",COMPETITOR_BENCHMARK!K13) -> No comp data | K15: =IF(OPTIMIZER!B10="","",IF(ABS(OPTIMIZER!U10)<0.005,"Hold. ",IF(OPTIMIZER!U10>0,IF(OPTIMIZER!U10<0.02,"Small raise. ",IF(OPTIMIZER!U10<0.05,"Modest raise. ","Notable raise. ")),IF(OPTIMIZER!U10>-0.02,"Small cut. ",IF(OPTIMIZER!U10>-0.05,"Modest cut. ","Notable cut. "))))&IF(OPTIMIZER!D10="Traffic Driver","Traffic Driver — protect entry price. ",IF(AND(OR(OPTIMIZER!D10="Signature",OPTIMIZER!D10="Premium Anchor"),MENU_ENGINEERING!K14="Dog"),OPTIMIZER!D10&" role in Dog quadrant — protect intentionally. ",IF(MENU_ENGINEERING!K14="Star","Star — protect leadership. ",IF(MENU_ENGINEERING!K14="Plowhorse","Plowhorse — capture margin. ",IF(MENU_ENGINEERING!K14="Puzzle","Puzzle — promote or reposition. ",IF(MENU_ENGINEERING!K14="Dog","Dog — consider removal. ",""))))))&IF(OPTIMIZER!J10="HIGH","Ship now.",IF(OPTIMIZER!J10="MEDIUM","Test first.","Pilot small — using prior."))) -> Modest raise. Premium Anchor role in Dog quadrant — protect intentionally. Pilot small — using prior.
A16: =IF(OPTIMIZER!B11="","",OPTIMIZER!B11) -> Cheesecake | B16: =IF(OPTIMIZER!B11="","",IF(ABS(OPTIMIZER!U11)<0.005,"Hold",IF(OPTIMIZER!U11>0,"Raise","Cut"))) -> Raise | C16: =IF(OPTIMIZER!B11="","",OPTIMIZER!F11) -> 5.8 | D16: =IF(OPTIMIZER!B11="","",OPTIMIZER!T11) -> 6.1 | E16: =IF(OPTIMIZER!B11="","",OPTIMIZER!U11) -> 0.051724138 | F16: =IF(OPTIMIZER!B11="","",OPTIMIZER!X11) -> 46.47541 | G16: =IF(OPTIMIZER!B11="","",OPTIMIZER!J11) -> LOW | H16: =IF(OPTIMIZER!B11="","",IF(ABS(OPTIMIZER!U11)<0.005,"Hold",IF(OPTIMIZER!J11="HIGH","Now","Pilot first"))) -> Pilot first | I16: =IF(OPTIMIZER!B11="","",MENU_ENGINEERING!K15) -> Puzzle | J16: =IF(OPTIMIZER!B11="","",COMPETITOR_BENCHMARK!K14) -> No comp data | K16: =IF(OPTIMIZER!B11="","",IF(ABS(OPTIMIZER!U11)<0.005,"Hold. ",IF(OPTIMIZER!U11>0,IF(OPTIMIZER!U11<0.02,"Small raise. ",IF(OPTIMIZER!U11<0.05,"Modest raise. ","Notable raise. ")),IF(OPTIMIZER!U11>-0.02,"Small cut. ",IF(OPTIMIZER!U11>-0.05,"Modest cut. ","Notable cut. "))))&IF(OPTIMIZER!D11="Traffic Driver","Traffic Driver — protect entry price. ",IF(AND(OR(OPTIMIZER!D11="Signature",OPTIMIZER!D11="Premium Anchor"),MENU_ENGINEERING!K15="Dog"),OPTIMIZER!D11&" role in Dog quadrant — protect intentionally. ",IF(MENU_ENGINEERING!K15="Star","Star — protect leadership. ",IF(MENU_ENGINEERING!K15="Plowhorse","Plowhorse — capture margin. ",IF(MENU_ENGINEERING!K15="Puzzle","Puzzle — promote or reposition. ",IF(MENU_ENGINEERING!K15="Dog","Dog — consider removal. ",""))))))&IF(OPTIMIZER!J11="HIGH","Ship now.",IF(OPTIMIZER!J11="MEDIUM","Test first.","Pilot small — using prior."))) -> Notable raise. Puzzle — promote or reposition. Pilot small — using prior.
A17: =IF(OPTIMIZER!B12="","",OPTIMIZER!B12) | B17: =IF(OPTIMIZER!B12="","",IF(ABS(OPTIMIZER!U12)<0.005,"Hold",IF(OPTIMIZER!U12>0,"Raise","Cut"))) | C17: =IF(OPTIMIZER!B12="","",OPTIMIZER!F12) | D17: =IF(OPTIMIZER!B12="","",OPTIMIZER!T12) | E17: =IF(OPTIMIZER!B12="","",OPTIMIZER!U12) | F17: =IF(OPTIMIZER!B12="","",OPTIMIZER!X12) | G17: =IF(OPTIMIZER!B12="","",OPTIMIZER!J12) | H17: =IF(OPTIMIZER!B12="","",IF(ABS(OPTIMIZER!U12)<0.005,"Hold",IF(OPTIMIZER!J12="HIGH","Now","Pilot first"))) | I17: =IF(OPTIMIZER!B12="","",MENU_ENGINEERING!K16) | J17: =IF(OPTIMIZER!B12="","",COMPETITOR_BENCHMARK!K15) | K17: =IF(OPTIMIZER!B12="","",IF(ABS(OPTIMIZER!U12)<0.005,"Hold. ",IF(OPTIMIZER!U12>0,IF(OPTIMIZER!U12<0.02,"Small raise. ",IF(OPTIMIZER!U12<0.05,"Modest raise. ","Notable raise. ")),IF(OPTIMIZER!U12>-0.02,"Small cut. ",IF(OPTIMIZER!U12>-0.05,"Modest cut. ","Notable cut. "))))&IF(OPTIMIZER!D12="Traffic Driver","Traffic Driver — protect entry price. ",IF(AND(OR(OPTIMIZER!D12="Signature",OPTIMIZER!D12="Premium Anchor"),MENU_ENGINEERING!K16="Dog"),OPTIMIZER!D12&" role in Dog quadrant — protect intentionally. ",IF(MENU_ENGINEERING!K16="Star","Star — protect leadership. ",IF(MENU_ENGINEERING!K16="Plowhorse","Plowhorse — capture margin. ",IF(MENU_ENGINEERING!K16="Puzzle","Puzzle — promote or reposition. ",IF(MENU_ENGINEERING!K16="Dog","Dog — consider removal. ",""))))))&IF(OPTIMIZER!J12="HIGH","Ship now.",IF(OPTIMIZER!J12="MEDIUM","Test first.","Pilot small — using prior.")))
A18: =IF(OPTIMIZER!B13="","",OPTIMIZER!B13) | B18: =IF(OPTIMIZER!B13="","",IF(ABS(OPTIMIZER!U13)<0.005,"Hold",IF(OPTIMIZER!U13>0,"Raise","Cut"))) | C18: =IF(OPTIMIZER!B13="","",OPTIMIZER!F13) | D18: =IF(OPTIMIZER!B13="","",OPTIMIZER!T13) | E18: =IF(OPTIMIZER!B13="","",OPTIMIZER!U13) | F18: =IF(OPTIMIZER!B13="","",OPTIMIZER!X13) | G18: =IF(OPTIMIZER!B13="","",OPTIMIZER!J13) | H18: =IF(OPTIMIZER!B13="","",IF(ABS(OPTIMIZER!U13)<0.005,"Hold",IF(OPTIMIZER!J13="HIGH","Now","Pilot first"))) | I18: =IF(OPTIMIZER!B13="","",MENU_ENGINEERING!K17) | J18: =IF(OPTIMIZER!B13="","",COMPETITOR_BENCHMARK!K16) | K18: =IF(OPTIMIZER!B13="","",IF(ABS(OPTIMIZER!U13)<0.005,"Hold. ",IF(OPTIMIZER!U13>0,IF(OPTIMIZER!U13<0.02,"Small raise. ",IF(OPTIMIZER!U13<0.05,"Modest raise. ","Notable raise. ")),IF(OPTIMIZER!U13>-0.02,"Small cut. ",IF(OPTIMIZER!U13>-0.05,"Modest cut. ","Notable cut. "))))&IF(OPTIMIZER!D13="Traffic Driver","Traffic Driver — protect entry price. ",IF(AND(OR(OPTIMIZER!D13="Signature",OPTIMIZER!D13="Premium Anchor"),MENU_ENGINEERING!K17="Dog"),OPTIMIZER!D13&" role in Dog quadrant — protect intentionally. ",IF(MENU_ENGINEERING!K17="Star","Star — protect leadership. ",IF(MENU_ENGINEERING!K17="Plowhorse","Plowhorse — capture margin. ",IF(MENU_ENGINEERING!K17="Puzzle","Puzzle — promote or reposition. ",IF(MENU_ENGINEERING!K17="Dog","Dog — consider removal. ",""))))))&IF(OPTIMIZER!J13="HIGH","Ship now.",IF(OPTIMIZER!J13="MEDIUM","Test first.","Pilot small — using prior.")))
A19: =IF(OPTIMIZER!B14="","",OPTIMIZER!B14) | B19: =IF(OPTIMIZER!B14="","",IF(ABS(OPTIMIZER!U14)<0.005,"Hold",IF(OPTIMIZER!U14>0,"Raise","Cut"))) | C19: =IF(OPTIMIZER!B14="","",OPTIMIZER!F14) | D19: =IF(OPTIMIZER!B14="","",OPTIMIZER!T14) | E19: =IF(OPTIMIZER!B14="","",OPTIMIZER!U14) | F19: =IF(OPTIMIZER!B14="","",OPTIMIZER!X14) | G19: =IF(OPTIMIZER!B14="","",OPTIMIZER!J14) | H19: =IF(OPTIMIZER!B14="","",IF(ABS(OPTIMIZER!U14)<0.005,"Hold",IF(OPTIMIZER!J14="HIGH","Now","Pilot first"))) | I19: =IF(OPTIMIZER!B14="","",MENU_ENGINEERING!K18) | J19: =IF(OPTIMIZER!B14="","",COMPETITOR_BENCHMARK!K17) | K19: =IF(OPTIMIZER!B14="","",IF(ABS(OPTIMIZER!U14)<0.005,"Hold. ",IF(OPTIMIZER!U14>0,IF(OPTIMIZER!U14<0.02,"Small raise. ",IF(OPTIMIZER!U14<0.05,"Modest raise. ","Notable raise. ")),IF(OPTIMIZER!U14>-0.02,"Small cut. ",IF(OPTIMIZER!U14>-0.05,"Modest cut. ","Notable cut. "))))&IF(OPTIMIZER!D14="Traffic Driver","Traffic Driver — protect entry price. ",IF(AND(OR(OPTIMIZER!D14="Signature",OPTIMIZER!D14="Premium Anchor"),MENU_ENGINEERING!K18="Dog"),OPTIMIZER!D14&" role in Dog quadrant — protect intentionally. ",IF(MENU_ENGINEERING!K18="Star","Star — protect leadership. ",IF(MENU_ENGINEERING!K18="Plowhorse","Plowhorse — capture margin. ",IF(MENU_ENGINEERING!K18="Puzzle","Puzzle — promote or reposition. ",IF(MENU_ENGINEERING!K18="Dog","Dog — consider removal. ",""))))))&IF(OPTIMIZER!J14="HIGH","Ship now.",IF(OPTIMIZER!J14="MEDIUM","Test first.","Pilot small — using prior.")))
A20: =IF(OPTIMIZER!B15="","",OPTIMIZER!B15) | B20: =IF(OPTIMIZER!B15="","",IF(ABS(OPTIMIZER!U15)<0.005,"Hold",IF(OPTIMIZER!U15>0,"Raise","Cut"))) | C20: =IF(OPTIMIZER!B15="","",OPTIMIZER!F15) | D20: =IF(OPTIMIZER!B15="","",OPTIMIZER!T15) | E20: =IF(OPTIMIZER!B15="","",OPTIMIZER!U15) | F20: =IF(OPTIMIZER!B15="","",OPTIMIZER!X15) | G20: =IF(OPTIMIZER!B15="","",OPTIMIZER!J15) | H20: =IF(OPTIMIZER!B15="","",IF(ABS(OPTIMIZER!U15)<0.005,"Hold",IF(OPTIMIZER!J15="HIGH","Now","Pilot first"))) | I20: =IF(OPTIMIZER!B15="","",MENU_ENGINEERING!K19) | J20: =IF(OPTIMIZER!B15="","",COMPETITOR_BENCHMARK!K18) | K20: =IF(OPTIMIZER!B15="","",IF(ABS(OPTIMIZER!U15)<0.005,"Hold. ",IF(OPTIMIZER!U15>0,IF(OPTIMIZER!U15<0.02,"Small raise. ",IF(OPTIMIZER!U15<0.05,"Modest raise. ","Notable raise. ")),IF(OPTIMIZER!U15>-0.02,"Small cut. ",IF(OPTIMIZER!U15>-0.05,"Modest cut. ","Notable cut. "))))&IF(OPTIMIZER!D15="Traffic Driver","Traffic Driver — protect entry price. ",IF(AND(OR(OPTIMIZER!D15="Signature",OPTIMIZER!D15="Premium Anchor"),MENU_ENGINEERING!K19="Dog"),OPTIMIZER!D15&" role in Dog quadrant — protect intentionally. ",IF(MENU_ENGINEERING!K19="Star","Star — protect leadership. ",IF(MENU_ENGINEERING!K19="Plowhorse","Plowhorse — capture margin. ",IF(MENU_ENGINEERING!K19="Puzzle","Puzzle — promote or reposition. ",IF(MENU_ENGINEERING!K19="Dog","Dog — consider removal. ",""))))))&IF(OPTIMIZER!J15="HIGH","Ship now.",IF(OPTIMIZER!J15="MEDIUM","Test first.","Pilot small — using prior.")))
A21: =IF(OPTIMIZER!B16="","",OPTIMIZER!B16) | B21: =IF(OPTIMIZER!B16="","",IF(ABS(OPTIMIZER!U16)<0.005,"Hold",IF(OPTIMIZER!U16>0,"Raise","Cut"))) | C21: =IF(OPTIMIZER!B16="","",OPTIMIZER!F16) | D21: =IF(OPTIMIZER!B16="","",OPTIMIZER!T16) | E21: =IF(OPTIMIZER!B16="","",OPTIMIZER!U16) | F21: =IF(OPTIMIZER!B16="","",OPTIMIZER!X16) | G21: =IF(OPTIMIZER!B16="","",OPTIMIZER!J16) | H21: =IF(OPTIMIZER!B16="","",IF(ABS(OPTIMIZER!U16)<0.005,"Hold",IF(OPTIMIZER!J16="HIGH","Now","Pilot first"))) | I21: =IF(OPTIMIZER!B16="","",MENU_ENGINEERING!K20) | J21: =IF(OPTIMIZER!B16="","",COMPETITOR_BENCHMARK!K19) | K21: =IF(OPTIMIZER!B16="","",IF(ABS(OPTIMIZER!U16)<0.005,"Hold. ",IF(OPTIMIZER!U16>0,IF(OPTIMIZER!U16<0.02,"Small raise. ",IF(OPTIMIZER!U16<0.05,"Modest raise. ","Notable raise. ")),IF(OPTIMIZER!U16>-0.02,"Small cut. ",IF(OPTIMIZER!U16>-0.05,"Modest cut. ","Notable cut. "))))&IF(OPTIMIZER!D16="Traffic Driver","Traffic Driver — protect entry price. ",IF(AND(OR(OPTIMIZER!D16="Signature",OPTIMIZER!D16="Premium Anchor"),MENU_ENGINEERING!K20="Dog"),OPTIMIZER!D16&" role in Dog quadrant — protect intentionally. ",IF(MENU_ENGINEERING!K20="Star","Star — protect leadership. ",IF(MENU_ENGINEERING!K20="Plowhorse","Plowhorse — capture margin. ",IF(MENU_ENGINEERING!K20="Puzzle","Puzzle — promote or reposition. ",IF(MENU_ENGINEERING!K20="Dog","Dog — consider removal. ",""))))))&IF(OPTIMIZER!J16="HIGH","Ship now.",IF(OPTIMIZER!J16="MEDIUM","Test first.","Pilot small — using prior.")))
A22: =IF(OPTIMIZER!B17="","",OPTIMIZER!B17) | B22: =IF(OPTIMIZER!B17="","",IF(ABS(OPTIMIZER!U17)<0.005,"Hold",IF(OPTIMIZER!U17>0,"Raise","Cut"))) | C22: =IF(OPTIMIZER!B17="","",OPTIMIZER!F17) | D22: =IF(OPTIMIZER!B17="","",OPTIMIZER!T17) | E22: =IF(OPTIMIZER!B17="","",OPTIMIZER!U17) | F22: =IF(OPTIMIZER!B17="","",OPTIMIZER!X17) | G22: =IF(OPTIMIZER!B17="","",OPTIMIZER!J17) | H22: =IF(OPTIMIZER!B17="","",IF(ABS(OPTIMIZER!U17)<0.005,"Hold",IF(OPTIMIZER!J17="HIGH","Now","Pilot first"))) | I22: =IF(OPTIMIZER!B17="","",MENU_ENGINEERING!K21) | J22: =IF(OPTIMIZER!B17="","",COMPETITOR_BENCHMARK!K20) | K22: =IF(OPTIMIZER!B17="","",IF(ABS(OPTIMIZER!U17)<0.005,"Hold. ",IF(OPTIMIZER!U17>0,IF(OPTIMIZER!U17<0.02,"Small raise. ",IF(OPTIMIZER!U17<0.05,"Modest raise. ","Notable raise. ")),IF(OPTIMIZER!U17>-0.02,"Small cut. ",IF(OPTIMIZER!U17>-0.05,"Modest cut. ","Notable cut. "))))&IF(OPTIMIZER!D17="Traffic Driver","Traffic Driver — protect entry price. ",IF(AND(OR(OPTIMIZER!D17="Signature",OPTIMIZER!D17="Premium Anchor"),MENU_ENGINEERING!K21="Dog"),OPTIMIZER!D17&" role in Dog quadrant — protect intentionally. ",IF(MENU_ENGINEERING!K21="Star","Star — protect leadership. ",IF(MENU_ENGINEERING!K21="Plowhorse","Plowhorse — capture margin. ",IF(MENU_ENGINEERING!K21="Puzzle","Puzzle — promote or reposition. ",IF(MENU_ENGINEERING!K21="Dog","Dog — consider removal. ",""))))))&IF(OPTIMIZER!J17="HIGH","Ship now.",IF(OPTIMIZER!J17="MEDIUM","Test first.","Pilot small — using prior.")))
... A40: =IF(OPTIMIZER!B35="","",OPTIMIZER!B35) | B40: =IF(OPTIMIZER!B35="","",IF(ABS(OPTIMIZER!U35)<0.005,"Hold",IF(OPTIMIZER!U35>0,"Raise","Cut"))) | C40: =IF(OPTIMIZER!B35="","",OPTIMIZER!F35) | D40: =IF(OPTIMIZER!B35="","",OPTIMIZER!T35) | E40: =IF(OPTIMIZER!B35="","",OPTIMIZER!U35) | F40: =IF(OPTIMIZER!B35="","",OPTIMIZER!X35) | G40: =IF(OPTIMIZER!B35="","",OPTIMIZER!J35) | H40: =IF(OPTIMIZER!B35="","",IF(ABS(OPTIMIZER!U35)<0.005,"Hold",IF(OPTIMIZER!J35="HIGH","Now","Pilot first"))) | I40: =IF(OPTIMIZER!B35="","",MENU_ENGINEERING!K39) | J40: =IF(OPTIMIZER!B35="","",COMPETITOR_BENCHMARK!K38) | K40: =IF(OPTIMIZER!B35="","",IF(ABS(OPTIMIZER!U35)<0.005,"Hold. ",IF(OPTIMIZER!U35>0,IF(OPTIMIZER!U35<0.02,"Small raise. ",IF(OPTIMIZER!U35<0.05,"Modest raise. ","Notable raise. ")),IF(OPTIMIZER!U35>-0.02,"Small cut. ",IF(OPTIMIZER!U35>-0.05,"Modest cut. ","Notable cut. "))))&IF(OPTIMIZER!D35="Traffic Driver","Traffic Driver — protect entry price. ",IF(AND(OR(OPTIMIZER!D35="Signature",OPTIMIZER!D35="Premium Anchor"),MENU_ENGINEERING!K39="Dog"),OPTIMIZER!D35&" role in Dog quadrant — protect intentionally. ",IF(MENU_ENGINEERING!K39="Star","Star — protect leadership. ",IF(MENU_ENGINEERING!K39="Plowhorse","Plowhorse — capture margin. ",IF(MENU_ENGINEERING!K39="Puzzle","Puzzle — promote or reposition. ",IF(MENU_ENGINEERING!K39="Dog","Dog — consider removal. ",""))))))&IF(OPTIMIZER!J35="HIGH","Ship now.",IF(OPTIMIZER!J35="MEDIUM","Test first.","Pilot small — using prior.")))
A41: TOTAL MONTHLY Δ PROFIT | F41: =opt_total_lift -> 372.23205
A44: What this recommendation is based on
A45: Customer price sensitivity | B45: Estimated from your sales data if available (HIGH/MEDIUM confidence); otherwise category-level priors are used (LOW confidence — recommendations are smaller and labelled "Pilot first").
A46: Your guardrails | B46: ="No item moves more than "&TEXT(cfg_max_raise,"+0%")&" or less than "&TEXT(cfg_max_cut,"0%")&" — set on SETTINGS. Role-based caps are tighter for traffic-driver items." -> No item moves more than +10% or less than -5% — set on SETTINGS. Role-based caps are tighter for traffic-driver items.
A47: Your cost numbers | B47: Update OWNER_INPUTS!E column when costs change; recommendations refresh automatically.
A48: Psychology | B48: Prices are pulled below major thresholds (5.00, 10.00, etc. in USD; 5000, 10000 etc. in IDR) when they would otherwise just barely cross.
A50: Want to dig deeper?
A51: =HYPERLINK("#'OPTIMIZER'!A1","OPTIMIZER") -> OPTIMIZER | B51: See the full pipeline — Lerner math, shrinkage, role caps, guardrails, thresholds, rounding.
A52: =HYPERLINK("#'CALIBRATION'!A1","CALIBRATION") -> CALIBRATION | B52: See per-item elasticity estimates with 95% confidence intervals.
A53: =HYPERLINK("#'PSYCHOLOGY_RULES'!A1","PSYCHOLOGY_RULES") -> PSYCHOLOGY_RULES | B53: See the role caps and threshold tables that the model uses.
A54: =HYPERLINK("#'CATEGORY_PRIORS'!A1","CATEGORY_PRIORS") -> CATEGORY_PRIORS | B54: Edit the default category elasticities used when data is missing.
A55: =HYPERLINK("#'MENU_ENGINEERING'!A1","MENU_ENGINEERING") -> MENU_ENGINEERING | B55: See how each item is classified as Star, Plowhorse, Puzzle, or Dog.
A56: =HYPERLINK("#'SENSITIVITY'!A1","SENSITIVITY") -> SENSITIVITY | B56: See the conservative / baseline / optimistic profit lift under different elasticity assumptions.
A57: =HYPERLINK("#'COMPETITOR_BENCHMARK'!A1","COMPETITOR_BENCHMARK") -> COMPETITOR_BENCHMARK | B57: Enter local competitor prices (optional) to see if any recommendation breaches the local market range.
A60: Sensitivity Check
A61: Conservative (e×1.2) | B61: =SENSITIVITY!H40 -> 247.96726 | C61: Profit lift if customers are MORE price-sensitive than assumed.
A62: Baseline (e×1.0) | B62: =SENSITIVITY!I40 -> 372.23205 | C62: Profit lift at the baseline elasticity used by the optimizer.
A63: Optimistic (e×0.8) | B63: =SENSITIVITY!J40 -> 497.25255 | C63: Profit lift if customers are LESS price-sensitive than assumed.
A64: Robust? | B64: =IF(AND(SENSITIVITY!H40>=0,SENSITIVITY!I40>=0,SENSITIVITY!J40>=0),"Yes — positive across all scenarios","No — at least one scenario negative") -> Yes — positive across all scenarios

Sheet CATEGORY_PRIORS
A1: Category Elasticity Priors (used when no client data is available)
A3: Each row is a default own-price elasticity assumption used when the model has no client-specific data. Negative numbers — more negative means customers react more strongly to price changes. These are starting assumptions only. Replace with estimates from CALIBRATION as real data comes in.
A5: Category | B5: Elasticity (prior) | C5: Source | D5: Sensitivity tier | E5: Notes
A6: Coffee | B6: -1.1 | C6: Manual Tab 4 | D6: Moderate | E6: Daily routine; competitive market.
A7: Specialty Drink | B7: -1.3 | C7: Manual Tab 4 | D7: Sensitive | E7: Substitutes within drink menu.
A8: Tea | B8: -1 | C8: Manual Tab 4 | D8: Moderate | E8: Comparable to coffee but lower volume.
A9: Pastry | B9: -0.9 | C9: Manual Tab 4 | D9: Inelastic | E9: Often impulse-bought as add-on.
A10: Dessert | B10: -1 | C10: Manual Tab 4 | D10: Moderate | E10: Special occasion items.
A11: Sandwich/Food | B11: -0.8 | C11: Manual Tab 4 | D11: Inelastic | E11: Brunch and food less substitutable.
A12: Bundle | B12: -0.95 | C12: Estimated | D12: Moderate | E12: Treat as basket; cross effects apply.
A13: Complement | B13: -0.7 | C13: Estimated | D13: Inelastic | E13: Sides, add-ons; basket effect dominates.
A14: Other | B14: -1.1 | C14: Default | D14: Moderate | E14: Fallback when category is unspecified.

Sheet PSYCHOLOGY_RULES
A1: Psychology Rules — Role caps and threshold management
A3: These rules constrain raw model output to keep recommendations psychologically credible. Role caps limit how much any single item can move, by its strategic role on the menu. Test increments are the small moves used when confidence is LOW — when the model is working off priors, not real data.
A5: Role caps
A6: Role | B6: Max raise (role cap) | C6: Max cut (role floor) | D6: Test increment (LOW conf.) | E6: Description | F6: Default action when no data
A7: Traffic Driver | B7: 0.03 | C7: -0.05 | D7: 0 | E7: Sharp entry price that signals fairness. Protect. | F7: Hold
A8: Core | B8: 0.06 | C8: -0.05 | D8: 0.02 | E8: High-volume standard menu item. Moderate moves OK. | F8: Small test raise
A9: Profit Driver | B9: 0.1 | C9: -0.05 | D9: 0.05 | E9: High-margin item that can carry most of the gain. | F9: Modest test raise
A10: Premium Anchor | B10: 0.1 | C10: -0.05 | D10: 0.05 | E10: Expensive reference point; protect premium feel. | F10: Modest test raise
A11: Signature | B11: 0.1 | C11: -0.05 | D11: 0.05 | E11: Brand-defining item; can carry premium pricing. | F11: Modest test raise
A12: Complement | B12: 0.07 | C12: -0.05 | D12: 0.03 | E12: Side/add-on; basket effect dominates. | F12: Small test raise
A13: Other | B13: 0.05 | C13: -0.05 | D13: 0.02 | E13: Unspecified role — conservative default. | F13: Small test raise
A16: Psychological thresholds
A17: If the rounded recommended price would land within "Buffer" above one of these thresholds, the model pulls the price down to threshold - 0.05 (USD) or threshold - 500 (IDR) instead. These represent perceptual jumps customers notice.
A19: USD thresholds | B19: Buffer (USD) | D19: IDR thresholds | E19: Buffer (IDR)
A20: 1 | B20: 0.2 | D20: 5000 | E20: 500
A21: 2 | B21: 0.2 | D21: 10000 | E21: 500
A22: 5 | B22: 0.2 | D22: 15000 | E22: 500
A23: 10 | B23: 0.3 | D23: 25000 | E23: 1000
A24: 15 | B24: 0.3 | D24: 50000 | E24: 1500
A25: 20 | B25: 0.4 | D25: 75000 | E25: 2000
A26: 50 | B26: 0.5 | D26: 100000 | E26: 3000
A27: 100 | B27: 1 | D27: 150000 | E27: 4000

Sheet MENU_ENGINEERING
A1: Menu Engineering — Star / Plowhorse / Puzzle / Dog
A3: Classifies each item by popularity (monthly units) and margin %, using menu medians as thresholds. Items above median on both axes are Stars; below on both are Dogs. The quadrant guides the recommended action.
A5: Median monthly units | B5: =IFERROR(MEDIAN($E$10:$E$39),0) -> 975 | C5: Items at or above this volume → "high popularity"
A6: Median margin % | B6: =IFERROR(MEDIAN($H$10:$H$39),0) -> 0.62010188 | C6: Items at or above this margin → "high margin"
A9: # | B9: Item | C9: Category | D9: Role | E9: Monthly units | F9: Unit margin | G9: Monthly profit | H9: Margin % | I9: Popularity tier | J9: Margin tier | K9: Quadrant | L9: Action | M9: Narrative
A10: 1 | B10: =IF(OWNER_INPUTS!B6="","",OWNER_INPUTS!B6) -> Flat White | C10: =IF($B10="","",OWNER_INPUTS!C6) -> Coffee | D10: =IF($B10="","",OWNER_INPUTS!D6) -> Traffic Driver | E10: =IF($B10="","",OWNER_INPUTS!G6) -> 1500 | F10: =IF($B10="","",OWNER_INPUTS!F6-OWNER_INPUTS!E6) -> 3.2 | G10: =IF($B10="","",$E10*$F10) -> 4800 | H10: =IF($B10="","",IF(OWNER_INPUTS!F6>0,$F10/OWNER_INPUTS!F6,0)) -> 0.76190476 | I10: =IF($B10="","",IF($E10>=$B$5,"High","Low")) -> High | J10: =IF($B10="","",IF($H10>=$B$6,"High","Low")) -> High | K10: =IF($B10="","",IF(AND($I10="High",$J10="High"),"Star",IF(AND($I10="High",$J10="Low"),"Plowhorse",IF(AND($I10="Low",$J10="High"),"Puzzle","Dog")))) -> Star | L10: =IF($B10="","",IF($K10="Star","Hold / protect leadership",IF($K10="Plowhorse","Modest raise to capture margin",IF($K10="Puzzle","Reposition / promote / test premium","Consider removal or simplification")))) -> Hold / protect leadership | M10: =IF($B10="","",$K10&" ("&$I10&" volume, "&$J10&" margin). "&$L10&".") -> Star (High volume, High margin). Hold / protect leadership.
A11: 2 | B11: =IF(OWNER_INPUTS!B7="","",OWNER_INPUTS!B7) -> Matcha Latte | C11: =IF($B11="","",OWNER_INPUTS!C7) -> Specialty Drink | D11: =IF($B11="","",OWNER_INPUTS!D7) -> Profit Driver | E11: =IF($B11="","",OWNER_INPUTS!G7) -> 1200 | F11: =IF($B11="","",OWNER_INPUTS!F7-OWNER_INPUTS!E7) -> 3.4 | G11: =IF($B11="","",$E11*$F11) -> 4080 | H11: =IF($B11="","",IF(OWNER_INPUTS!F7>0,$F11/OWNER_INPUTS!F7,0)) -> 0.70833333 | I11: =IF($B11="","",IF($E11>=$B$5,"High","Low")) -> High | J11: =IF($B11="","",IF($H11>=$B$6,"High","Low")) -> High | K11: =IF($B11="","",IF(AND($I11="High",$J11="High"),"Star",IF(AND($I11="High",$J11="Low"),"Plowhorse",IF(AND($I11="Low",$J11="High"),"Puzzle","Dog")))) -> Star | L11: =IF($B11="","",IF($K11="Star","Hold / protect leadership",IF($K11="Plowhorse","Modest raise to capture margin",IF($K11="Puzzle","Reposition / promote / test premium","Consider removal or simplification")))) -> Hold / protect leadership | M11: =IF($B11="","",$K11&" ("&$I11&" volume, "&$J11&" margin). "&$L11&".") -> Star (High volume, High margin). Hold / protect leadership.
A12: 3 | B12: =IF(OWNER_INPUTS!B8="","",OWNER_INPUTS!B8) -> Eggs Benedict | C12: =IF($B12="","",OWNER_INPUTS!C8) -> Sandwich/Food | D12: =IF($B12="","",OWNER_INPUTS!D8) -> Signature | E12: =IF($B12="","",OWNER_INPUTS!G8) -> 900 | F12: =IF($B12="","",OWNER_INPUTS!F8-OWNER_INPUTS!E8) -> 5.6 | G12: =IF($B12="","",$E12*$F12) -> 5040 | H12: =IF($B12="","",IF(OWNER_INPUTS!F8>0,$F12/OWNER_INPUTS!F8,0)) -> 0.57142857 | I12: =IF($B12="","",IF($E12>=$B$5,"High","Low")) -> Low | J12: =IF($B12="","",IF($H12>=$B$6,"High","Low")) -> Low | K12: =IF($B12="","",IF(AND($I12="High",$J12="High"),"Star",IF(AND($I12="High",$J12="Low"),"Plowhorse",IF(AND($I12="Low",$J12="High"),"Puzzle","Dog")))) -> Dog | L12: =IF($B12="","",IF($K12="Star","Hold / protect leadership",IF($K12="Plowhorse","Modest raise to capture margin",IF($K12="Puzzle","Reposition / promote / test premium","Consider removal or simplification")))) -> Consider removal or simplification | M12: =IF($B12="","",$K12&" ("&$I12&" volume, "&$J12&" margin). "&$L12&".") -> Dog (Low volume, Low margin). Consider removal or simplification.
A13: 4 | B13: =IF(OWNER_INPUTS!B9="","",OWNER_INPUTS!B9) -> Avocado Toast | C13: =IF($B13="","",OWNER_INPUTS!C9) -> Sandwich/Food | D13: =IF($B13="","",OWNER_INPUTS!D9) -> Core | E13: =IF($B13="","",OWNER_INPUTS!G9) -> 1050 | F13: =IF($B13="","",OWNER_INPUTS!F9-OWNER_INPUTS!E9) -> 6 | G13: =IF($B13="","",$E13*$F13) -> 6300 | H13: =IF($B13="","",IF(OWNER_INPUTS!F9>0,$F13/OWNER_INPUTS!F9,0)) -> 0.57142857 | I13: =IF($B13="","",IF($E13>=$B$5,"High","Low")) -> High | J13: =IF($B13="","",IF($H13>=$B$6,"High","Low")) -> Low | K13: =IF($B13="","",IF(AND($I13="High",$J13="High"),"Star",IF(AND($I13="High",$J13="Low"),"Plowhorse",IF(AND($I13="Low",$J13="High"),"Puzzle","Dog")))) -> Plowhorse | L13: =IF($B13="","",IF($K13="Star","Hold / protect leadership",IF($K13="Plowhorse","Modest raise to capture margin",IF($K13="Puzzle","Reposition / promote / test premium","Consider removal or simplification")))) -> Modest raise to capture margin | M13: =IF($B13="","",$K13&" ("&$I13&" volume, "&$J13&" margin). "&$L13&".") -> Plowhorse (High volume, Low margin). Modest raise to capture margin.
A14: 5 | B14: =IF(OWNER_INPUTS!B10="","",OWNER_INPUTS!B10) -> Pancakes | C14: =IF($B14="","",OWNER_INPUTS!C10) -> Pastry | D14: =IF($B14="","",OWNER_INPUTS!D10) -> Premium Anchor | E14: =IF($B14="","",OWNER_INPUTS!G10) -> 750 | F14: =IF($B14="","",OWNER_INPUTS!F10-OWNER_INPUTS!E10) -> 5.3 | G14: =IF($B14="","",$E14*$F14) -> 3975 | H14: =IF($B14="","",IF(OWNER_INPUTS!F10>0,$F14/OWNER_INPUTS!F10,0)) -> 0.60227273 | I14: =IF($B14="","",IF($E14>=$B$5,"High","Low")) -> Low | J14: =IF($B14="","",IF($H14>=$B$6,"High","Low")) -> Low | K14: =IF($B14="","",IF(AND($I14="High",$J14="High"),"Star",IF(AND($I14="High",$J14="Low"),"Plowhorse",IF(AND($I14="Low",$J14="High"),"Puzzle","Dog")))) -> Dog | L14: =IF($B14="","",IF($K14="Star","Hold / protect leadership",IF($K14="Plowhorse","Modest raise to capture margin",IF($K14="Puzzle","Reposition / promote / test premium","Consider removal or simplification")))) -> Consider removal or simplification | M14: =IF($B14="","",$K14&" ("&$I14&" volume, "&$J14&" margin). "&$L14&".") -> Dog (Low volume, Low margin). Consider removal or simplification.
A15: 6 | B15: =IF(OWNER_INPUTS!B11="","",OWNER_INPUTS!B11) -> Cheesecake | C15: =IF($B15="","",OWNER_INPUTS!C11) -> Dessert | D15: =IF($B15="","",OWNER_INPUTS!D11) -> Profit Driver | E15: =IF($B15="","",OWNER_INPUTS!G11) -> 450 | F15: =IF($B15="","",OWNER_INPUTS!F11-OWNER_INPUTS!E11) -> 3.7 | G15: =IF($B15="","",$E15*$F15) -> 1665 | H15: =IF($B15="","",IF(OWNER_INPUTS!F11>0,$F15/OWNER_INPUTS!F11,0)) -> 0.63793103 | I15: =IF($B15="","",IF($E15>=$B$5,"High","Low")) -> Low | J15: =IF($B15="","",IF($H15>=$B$6,"High","Low")) -> High | K15: =IF($B15="","",IF(AND($I15="High",$J15="High"),"Star",IF(AND($I15="High",$J15="Low"),"Plowhorse",IF(AND($I15="Low",$J15="High"),"Puzzle","Dog")))) -> Puzzle | L15: =IF($B15="","",IF($K15="Star","Hold / protect leadership",IF($K15="Plowhorse","Modest raise to capture margin",IF($K15="Puzzle","Reposition / promote / test premium","Consider removal or simplification")))) -> Reposition / promote / test premium | M15: =IF($B15="","",$K15&" ("&$I15&" volume, "&$J15&" margin). "&$L15&".") -> Puzzle (Low volume, High margin). Reposition / promote / test premium.
A16: 7 | B16: =IF(OWNER_INPUTS!B12="","",OWNER_INPUTS!B12) | C16: =IF($B16="","",OWNER_INPUTS!C12) | D16: =IF($B16="","",OWNER_INPUTS!D12) | E16: =IF($B16="","",OWNER_INPUTS!G12) | F16: =IF($B16="","",OWNER_INPUTS!F12-OWNER_INPUTS!E12) | G16: =IF($B16="","",$E16*$F16) | H16: =IF($B16="","",IF(OWNER_INPUTS!F12>0,$F16/OWNER_INPUTS!F12,0)) | I16: =IF($B16="","",IF($E16>=$B$5,"High","Low")) | J16: =IF($B16="","",IF($H16>=$B$6,"High","Low")) | K16: =IF($B16="","",IF(AND($I16="High",$J16="High"),"Star",IF(AND($I16="High",$J16="Low"),"Plowhorse",IF(AND($I16="Low",$J16="High"),"Puzzle","Dog")))) | L16: =IF($B16="","",IF($K16="Star","Hold / protect leadership",IF($K16="Plowhorse","Modest raise to capture margin",IF($K16="Puzzle","Reposition / promote / test premium","Consider removal or simplification")))) | M16: =IF($B16="","",$K16&" ("&$I16&" volume, "&$J16&" margin). "&$L16&".")
A17: 8 | B17: =IF(OWNER_INPUTS!B13="","",OWNER_INPUTS!B13) | C17: =IF($B17="","",OWNER_INPUTS!C13) | D17: =IF($B17="","",OWNER_INPUTS!D13) | E17: =IF($B17="","",OWNER_INPUTS!G13) | F17: =IF($B17="","",OWNER_INPUTS!F13-OWNER_INPUTS!E13) | G17: =IF($B17="","",$E17*$F17) | H17: =IF($B17="","",IF(OWNER_INPUTS!F13>0,$F17/OWNER_INPUTS!F13,0)) | I17: =IF($B17="","",IF($E17>=$B$5,"High","Low")) | J17: =IF($B17="","",IF($H17>=$B$6,"High","Low")) | K17: =IF($B17="","",IF(AND($I17="High",$J17="High"),"Star",IF(AND($I17="High",$J17="Low"),"Plowhorse",IF(AND($I17="Low",$J17="High"),"Puzzle","Dog")))) | L17: =IF($B17="","",IF($K17="Star","Hold / protect leadership",IF($K17="Plowhorse","Modest raise to capture margin",IF($K17="Puzzle","Reposition / promote / test premium","Consider removal or simplification")))) | M17: =IF($B17="","",$K17&" ("&$I17&" volume, "&$J17&" margin). "&$L17&".")
A18: 9 | B18: =IF(OWNER_INPUTS!B14="","",OWNER_INPUTS!B14) | C18: =IF($B18="","",OWNER_INPUTS!C14) | D18: =IF($B18="","",OWNER_INPUTS!D14) | E18: =IF($B18="","",OWNER_INPUTS!G14) | F18: =IF($B18="","",OWNER_INPUTS!F14-OWNER_INPUTS!E14) | G18: =IF($B18="","",$E18*$F18) | H18: =IF($B18="","",IF(OWNER_INPUTS!F14>0,$F18/OWNER_INPUTS!F14,0)) | I18: =IF($B18="","",IF($E18>=$B$5,"High","Low")) | J18: =IF($B18="","",IF($H18>=$B$6,"High","Low")) | K18: =IF($B18="","",IF(AND($I18="High",$J18="High"),"Star",IF(AND($I18="High",$J18="Low"),"Plowhorse",IF(AND($I18="Low",$J18="High"),"Puzzle","Dog")))) | L18: =IF($B18="","",IF($K18="Star","Hold / protect leadership",IF($K18="Plowhorse","Modest raise to capture margin",IF($K18="Puzzle","Reposition / promote / test premium","Consider removal or simplification")))) | M18: =IF($B18="","",$K18&" ("&$I18&" volume, "&$J18&" margin). "&$L18&".")
A19: 10 | B19: =IF(OWNER_INPUTS!B15="","",OWNER_INPUTS!B15) | C19: =IF($B19="","",OWNER_INPUTS!C15) | D19: =IF($B19="","",OWNER_INPUTS!D15) | E19: =IF($B19="","",OWNER_INPUTS!G15) | F19: =IF($B19="","",OWNER_INPUTS!F15-OWNER_INPUTS!E15) | G19: =IF($B19="","",$E19*$F19) | H19: =IF($B19="","",IF(OWNER_INPUTS!F15>0,$F19/OWNER_INPUTS!F15,0)) | I19: =IF($B19="","",IF($E19>=$B$5,"High","Low")) | J19: =IF($B19="","",IF($H19>=$B$6,"High","Low")) | K19: =IF($B19="","",IF(AND($I19="High",$J19="High"),"Star",IF(AND($I19="High",$J19="Low"),"Plowhorse",IF(AND($I19="Low",$J19="High"),"Puzzle","Dog")))) | L19: =IF($B19="","",IF($K19="Star","Hold / protect leadership",IF($K19="Plowhorse","Modest raise to capture margin",IF($K19="Puzzle","Reposition / promote / test premium","Consider removal or simplification")))) | M19: =IF($B19="","",$K19&" ("&$I19&" volume, "&$J19&" margin). "&$L19&".")
A20: 11 | B20: =IF(OWNER_INPUTS!B16="","",OWNER_INPUTS!B16) | C20: =IF($B20="","",OWNER_INPUTS!C16) | D20: =IF($B20="","",OWNER_INPUTS!D16) | E20: =IF($B20="","",OWNER_INPUTS!G16) | F20: =IF($B20="","",OWNER_INPUTS!F16-OWNER_INPUTS!E16) | G20: =IF($B20="","",$E20*$F20) | H20: =IF($B20="","",IF(OWNER_INPUTS!F16>0,$F20/OWNER_INPUTS!F16,0)) | I20: =IF($B20="","",IF($E20>=$B$5,"High","Low")) | J20: =IF($B20="","",IF($H20>=$B$6,"High","Low")) | K20: =IF($B20="","",IF(AND($I20="High",$J20="High"),"Star",IF(AND($I20="High",$J20="Low"),"Plowhorse",IF(AND($I20="Low",$J20="High"),"Puzzle","Dog")))) | L20: =IF($B20="","",IF($K20="Star","Hold / protect leadership",IF($K20="Plowhorse","Modest raise to capture margin",IF($K20="Puzzle","Reposition / promote / test premium","Consider removal or simplification")))) | M20: =IF($B20="","",$K20&" ("&$I20&" volume, "&$J20&" margin). "&$L20&".")
A21: 12 | B21: =IF(OWNER_INPUTS!B17="","",OWNER_INPUTS!B17) | C21: =IF($B21="","",OWNER_INPUTS!C17) | D21: =IF($B21="","",OWNER_INPUTS!D17) | E21: =IF($B21="","",OWNER_INPUTS!G17) | F21: =IF($B21="","",OWNER_INPUTS!F17-OWNER_INPUTS!E17) | G21: =IF($B21="","",$E21*$F21) | H21: =IF($B21="","",IF(OWNER_INPUTS!F17>0,$F21/OWNER_INPUTS!F17,0)) | I21: =IF($B21="","",IF($E21>=$B$5,"High","Low")) | J21: =IF($B21="","",IF($H21>=$B$6,"High","Low")) | K21: =IF($B21="","",IF(AND($I21="High",$J21="High"),"Star",IF(AND($I21="High",$J21="Low"),"Plowhorse",IF(AND($I21="Low",$J21="High"),"Puzzle","Dog")))) | L21: =IF($B21="","",IF($K21="Star","Hold / protect leadership",IF($K21="Plowhorse","Modest raise to capture margin",IF($K21="Puzzle","Reposition / promote / test premium","Consider removal or simplification")))) | M21: =IF($B21="","",$K21&" ("&$I21&" volume, "&$J21&" margin). "&$L21&".")
... A39: 30 | B39: =IF(OWNER_INPUTS!B35="","",OWNER_INPUTS!B35) | C39: =IF($B39="","",OWNER_INPUTS!C35) | D39: =IF($B39="","",OWNER_INPUTS!D35) | E39: =IF($B39="","",OWNER_INPUTS!G35) | F39: =IF($B39="","",OWNER_INPUTS!F35-OWNER_INPUTS!E35) | G39: =IF($B39="","",$E39*$F39) | H39: =IF($B39="","",IF(OWNER_INPUTS!F35>0,$F39/OWNER_INPUTS!F35,0)) | I39: =IF($B39="","",IF($E39>=$B$5,"High","Low")) | J39: =IF($B39="","",IF($H39>=$B$6,"High","Low")) | K39: =IF($B39="","",IF(AND($I39="High",$J39="High"),"Star",IF(AND($I39="High",$J39="Low"),"Plowhorse",IF(AND($I39="Low",$J39="High"),"Puzzle","Dog")))) | L39: =IF($B39="","",IF($K39="Star","Hold / protect leadership",IF($K39="Plowhorse","Modest raise to capture margin",IF($K39="Puzzle","Reposition / promote / test premium","Consider removal or simplification")))) | M39: =IF($B39="","",$K39&" ("&$I39&" volume, "&$J39&" margin). "&$L39&".")
D40: Star count | E40: =COUNTIF($K$10:$K$39,"Star") -> 2
D41: Plowhorse count | E41: =COUNTIF($K$10:$K$39,"Plowhorse") -> 1
D42: Puzzle count | E42: =COUNTIF($K$10:$K$39,"Puzzle") -> 1
D43: Dog count | E43: =COUNTIF($K$10:$K$39,"Dog") -> 2
D44: Total items | E44: =SUMPRODUCT(--(LEN($B$10:$B$39)>0)) -> 6
D45: Menu balance | E45: =IF($E$40+$E$41+$E$42+$E$43=0,"No items configured",IF(($E$43/($E$40+$E$41+$E$42+$E$43))>0.3,"DOG-HEAVY — consider menu simplification",IF(($E$40+$E$41)/($E$40+$E$41+$E$42+$E$43)>=0.6,"BALANCED — popular items dominate","PUZZLE-HEAVY — many low-volume items, opportunity for promotion"))) -> DOG-HEAVY — consider menu simplification

Sheet SALES_DATA
A1: Daily Sales Data — for calibrating item-level price sensitivity
